<?xml version="1.0"?>
<robot name="my_robo" >
  <property name="M_PI" value="3.14159274"/>
  
  <!-- base -->
  <property name="bd"  value="0.330"/>
  <property name="bw"  value="0.330"/>
  <property name="bh"  value="0.900"/>
  <property name="base_mass" value="30.0"/>
  <property name="base_ixx" value="${1.0/12.0*base_mass*(bw*bw+bh*bh)}"/>
  <property name="base_iyy" value="${1.0/12.0*base_mass*(bh*bh+bd*bd)}"/>
  <property name="base_izz" value="${1.0/12.0*base_mass*(bw*bw+bd*bd)}"/>
  
  <!-- foot -->
  <property name="fd"  value="0.626"/>
  <property name="fw"  value="${bw}"/>
  <property name="fh"  value="0.010"/>
  <property name="fx"  value="${bd/2-(bd-fd/2)}"/>
  <property name="fy"  value="0"/>
  <property name="fz"  value="${-fh/2-bh/2}"/>
  <property name="foot_mass" value="3.0"/>
  <property name="foot_ixx" value="${1.0/12.0*foot_mass*(fw*fw+fh*fh)}"/>
  <property name="foot_iyy" value="${1.0/12.0*foot_mass*(fh*fh+fd*fd)}"/>
  <property name="foot_izz" value="${1.0/12.0*foot_mass*(fw*fw+fd*fd)}"/>
   
  <!-- wheel (parent frame: foot_link) -->
  <property name="wr" value="0.085"/>
  <property name="wl" value="0.056"/>
  <property name="wx" value="${-fd/2.0+wr}"/>
  <property name="wy" value="${fw/2.0+0.018+wl/2.0}"/>
  <property name="wz" value="${0.112-wr}"/>
  <property name="wheel_mass" value="1.5"/>
  <property name="wheel_ixx" value="${1.0/12.0*wheel_mass*(3.0*wr*wr+wl*wl)}"/>
  <property name="wheel_iyy" value="${1.0/12.0*wheel_mass*(3.0*wr*wr+wl*wl)}"/>
  <property name="wheel_izz" value="${1.0/2.0*wheel_mass*wr*wr}"/>

  <!-- caster -->
  <property name="cr" value="0.056"/>
  <property name="cx" value="${fd/8.0*3.0}"/>
  <property name="cy" value="0"/>
  <property name="cz" value="${fh/2.0+cr}"/>
  <property name="caster_mass" value="1.0"/>
  <property name="caster_i" value="${1.0/5.0*caster_mass*cr*cr}"/>

  <!-- neck -->
  <property name="nd"  value="0.05"/>
  <property name="nw"  value="0.05"/>
  <property name="nh"  value="0.05"/>
  <property name="nx" value="0"/>
  <property name="ny" value="0"/>
  <property name="nz" value="${bh/2.0+nh/2.0}"/>
  <property name="neck_mass" value="1.0"/>
  <property name="neck_ixx" value="${1.0/12.0*neck_mass*(nw*nw+nh*nh)}"/>
  <property name="neck_iyy" value="${1.0/12.0*neck_mass*(nh*nh+nd*nd)}"/>
  <property name="neck_izz" value="${1.0/12.0*neck_mass*(nw*nw+nd*nd)}"/>

  <!-- head -->
  <property name="hd" value="0.310"/>
  <property name="hw" value="0.330"/>
  <property name="hh" value="0.03"/>
  <property name="hx" value="0"/>
  <property name="hy" value="0"/>
  <property name="hz" value="${nh/2.0+hh/2.0}"/>
  <property name="head_mass" value="4.0"/>
  <property name="head_ixx" value="${1.0/12.0*head_mass*(hw*hw+hh*hh)}"/>
  <property name="head_iyy" value="${1.0/12.0*head_mass*(hh*hh+hd*hd)}"/>
  <property name="head_izz" value="${1.0/12.0*head_mass*(hw*hw+hd*hd)}"/>
  
  <!-- footprint -->
  <link name="base_footprint"/>
  
  <!-- base_link -->
  <link name="base_link">
    <visual>
      <geometry>
        <box size="${bd} ${bw} ${bh}"/>
      </geometry>
    </visual>
 
    <collision>
      <geometry>
        <box size="${bd} ${bw} ${bh}"/>
      </geometry>
    </collision>
 
    <inertial>
      <origin xyz="0 0 0"/>
      <mass value="${base_mass}"/>
      <inertia ixx="${base_ixx}" ixy="0" ixz="0" iyy="${base_iyy}" iyz="0" izz="${base_izz}"/>
    </inertial>
  </link>
  
  <joint name="base_link_joint" type="fixed">
    <parent link="base_footprint"/>
    <child link="base_link"/>
    <origin xyz="0 0 0"/>
  </joint>
  
  <!-- foot -->
  <link name="foot_link">
    <visual>
      <geometry>
        <box size="${fd} ${fw} ${fh}"/>
      </geometry>
    </visual>
 
    <collision>
      <geometry>
        <box size="${fd} ${fw} ${fh}"/>
      </geometry>
    </collision>
  </link>
  
  <joint name="foot_joint" type="fixed">
    <parent link="base_link"/>
    <child link="foot_link"/>
    <origin xyz="${fx} ${fy} ${fz}"/>
  </joint>

  <!-- neck_link -->
  <link name="neck_link">
    <visual>
      <geometry>
        <box size="${nd} ${nw} ${nh}"/>
      </geometry>
    </visual>
 
    <collision>
      <geometry>
        <box size="${nd} ${nw} ${nh}"/>
      </geometry>
    </collision>
 
    <inertial>
      <origin xyz="0 0 0"/>
      <mass value="${neck_mass}"/>
      <inertia ixx="${neck_ixx}" ixy="0" ixz="0" iyy="${neck_iyy}" iyz="0" izz="${neck_izz}"/>
    </inertial>
  </link>

  <joint name="neck_joint" type="revolute">
    <parent link="base_link"/>
    <child link="neck_link"/>
    <origin rpy="0 0 0" xyz="${nx} ${ny} ${nz}"/>
    <axis xyz="0 0 1"/>
    <limit lower="${-M_PI/180.0*40.0}" upper="${M_PI/180.0*40.0}" effort="0.5293" velocity="6.159937255"/>
  </joint>
  
  <!-- head_link -->
  <link name="head_link">
    <visual>
      <geometry>
        <box size="${hd} ${hw} ${hh}"/>
      </geometry>
    </visual>
 
    <collision>
      <geometry>
        <box size="${hd} ${hw} ${hh}"/>
      </geometry>
    </collision>
 
    <inertial>
      <origin xyz="0 0 0"/>
      <mass value="${head_mass}"/>
      <inertia ixx="${head_ixx}" ixy="0" ixz="0" iyy="${head_iyy}" iyz="0" izz="${head_izz}"/>
    </inertial>
  </link>

  <joint name="head_joint" type="revolute">
    <parent link="neck_link"/>
    <child link="head_link"/>
    <origin rpy="0 0 0" xyz="${hx} ${hy} ${hz}"/>
    <axis xyz="0 1 0"/>
    <limit lower="${-M_PI/180.0*20.0}" upper="${M_PI/180.0*20.0}" effort="0.5293" velocity="6.159937255"/>
  </joint>

  <!-- wheel -->
  <link name="left_wheel_link">
    <visual>
      <geometry>
        <cylinder radius="${wr}" length="${wl}"/>
      </geometry>
      <origin xyz="0 0 0" rpy="0 0 0"/>
      <material name="black"/>
    </visual>
 
    <collision>
      <geometry>
        <cylinder radius="${wr}" length="${wl}"/>
      </geometry>
    </collision>
 
    <inertial>
      <origin xyz="0 0 0"/>
      <mass value="${wheel_mass}"/>
      <inertia ixx="${wheel_ixx}" ixy="0" ixz="0" iyy="${wheel_iyy}" iyz="0" izz="${wheel_izz}"/>
    </inertial>
 
  </link>
 
  <joint name="left_wheel_joint" type="continuous">
    <parent link="foot_link"/>
    <child link="left_wheel_link"/>
    <origin rpy="${-M_PI/2} 0 0" xyz="${wx} ${wy} ${-wz}"/>
    <axis xyz="0 0 1"/>
  </joint>
 
  <link name="right_wheel_link">
    <visual>
      <geometry>
        <cylinder radius="${wr}" length="${wl}"/>
      </geometry>
      <origin xyz="0 0 0" rpy="0 0 0"/>
      <material name="black"/>
    </visual>
 
    <collision>
      <geometry>
        <cylinder radius="${wr}" length="${wl}"/>
      </geometry>
    </collision>
 
    <inertial>
      <origin xyz="0 0 0"/>
      <mass value="${wheel_mass}"/>
      <inertia ixx="${wheel_ixx}" ixy="0" ixz="0" iyy="${wheel_iyy}" iyz="0" izz="${wheel_izz}"/>
    </inertial>
 
  </link>
 
  <joint name="right_wheel_joint" type="continuous">
    <parent link="foot_link"/>
    <child link="right_wheel_link"/>
    <origin rpy="${M_PI/2} 0 0" xyz="${wx} ${-wy} ${-wz}"/>
    <axis xyz="0 0 -1"/>
  </joint>
 
  <!-- caster -->
  <link name="caster_link">
    <visual>
      <geometry>
        <sphere radius="${cr}"/>
      </geometry>
      <material name="green">
        <color rgba="0 1 0 1"/>
      </material>
    </visual>
 
    <collision>
      <geometry>
        <sphere radius="${cr}"/>
      </geometry>
    </collision>
 
    <inertial>
      <origin xyz="0 0 0"/>
      <mass value="${caster_mass}"/>
      <inertia ixx="${caster_i}" ixy="0" ixz="0" iyy="${caster_i}"  iyz="0" izz="${caster_i}"/>
    </inertial>
  </link>
 
  <joint name="caster_joint" type="fixed">
    <parent link="foot_link"/>
    <child link="caster_link"/>
    <origin xyz="${cx} ${cy} ${-cz}"/>
  </joint>
 
  <!-- Hokuyo Laser -->
  <link name="hokuyo_link">
    <collision>
      <origin xyz="0 0 0" rpy="0 0 0"/>
      <geometry>
        <box size="0.1 0.1 0.1"/>
      </geometry>
    </collision>
 
    <visual>
      <origin xyz="0 0 0" rpy="0 0 0"/>
      <geometry>
        <mesh filename="package://rrbot_description/meshes/hokuyo.dae"/>
      </geometry>
    </visual>
 
    <inertial>
      <mass value="1e-5" />
      <origin xyz="0 0 0" rpy="0 0 0"/>
      <inertia ixx="1e-6" ixy="0" ixz="0" iyy="1e-6" iyz="0" izz="1e-6" />
    </inertial>
  </link>
  
  <joint name="hokuyo_joint" type="fixed">
    <axis xyz="0 1 0" />
    <!--<origin xyz="${bd/2+0.05} 0 0" rpy="0 0 0"/>-->
    <origin xyz="${hd/2.0-0.015} 0 ${hh+0.02} " rpy="0 0 0"/>
    <parent link="head_link"/>
    <child link="hokuyo_link"/>
  </joint>
 
  <!-- The transmission element is used to describe the relationship between an actuator and a joint. -->
  <transmission name="left_wheel_trans">
    <type>transmission_interface/SimpleTransmission</type>
    <joint name="left_wheel_joint">
      <hardwareInterface>hardware_interface/VelocityJointInterface</hardwareInterface>
    </joint>
    <actuator name="left_wheel_motor">
      <hardwareInterface>hardware_interface/VelocityJointInterface</hardwareInterface>
      <mechanicalReduction>30</mechanicalReduction>
    </actuator>
  </transmission>
  <transmission name="right_wheel_trans">
    <type>transmission_interface/SimpleTransmission</type>
    <joint name="right_wheel_joint">
      <hardwareInterface>hardware_interface/VelocityJointInterface</hardwareInterface>
    </joint>
    <actuator name="right_wheel_motor">
      <hardwareInterface>hardware_interface/VelocityJointInterface</hardwareInterface>
      <mechanicalReduction>30</mechanicalReduction>
    </actuator>
  </transmission>
  

  <transmission name="head_trans">
    <type>transmission_interface/SimpleTransmission</type>
    <joint name="head_joint">
      <hardwareInterface>hardware_interface/EffortJointInterface</hardwareInterface>
    </joint>
    <actuator name="head_motor">
      <hardwareInterface>hardware_interface/EffortJointInterface</hardwareInterface>
      <mechanicalReduction>1</mechanicalReduction>
    </actuator>
  </transmission>

  <transmission name="neck_trans">
    <type>transmission_interface/SimpleTransmission</type>
    <joint name="neck_joint">
      <hardwareInterface>hardware_interface/EffortJointInterface</hardwareInterface>
    </joint>
    <actuator name="neck_motor">
      <hardwareInterface>hardware_interface/EffortJointInterface</hardwareInterface>
      <mechanicalReduction>1</mechanicalReduction>
    </actuator>
  </transmission>

  <gazebo>
    <plugin name="gazebo_ros_control" filename="libgazebo_ros_control.so">
      <robotNamespace>my_robo</robotNamespace>
    </plugin>
  </gazebo>
 
  <gazebo reference="base_link">
    <selfCollide>true</selfCollide>
    <mu1 value="0.05" />
    <mu2 value="0.05" />
  </gazebo>
 
  <gazebo reference="left_wheel_link">
    <selfCollide>true</selfCollide>
    <mu1 value="0.8" />
    <mu2 value="0.8" />
  </gazebo>
 
  <gazebo reference="right_wheel_link">
    <selfCollide>true</selfCollide>
    <mu1 value="0.8" />
    <mu2 value="0.8" />
  </gazebo>
 
  <gazebo reference="caster_link">
    <selfCollide>true</selfCollide>
    <!-- This caster is no frictional resistance. -->
    <mu1 value="0.0" />
    <mu2 value="0.0" />
  </gazebo>
  
 <gazebo reference="neck_link">
    <selfCollide>true</selfCollide>
    <mu1 value="0.8" />
    <mu2 value="0.8" />
  </gazebo>

 <gazebo reference="head_link">
    <selfCollide>true</selfCollide>
    <mu1 value="0.8" />
    <mu2 value="0.8" />
  </gazebo>

  <!-- hokuyo -->
  <gazebo reference="hokuyo_link">
    <sensor type="ray" name="head_hokuyo_sensor">
      <pose>0 0 0 0 0 0</pose>
      <visualize>false</visualize>
      <update_rate>40</update_rate>
      <ray>
        <scan>
          <horizontal>
            <samples>720</samples>
            <resolution>1</resolution>
            <min_angle>-1.570796</min_angle>
            <max_angle>1.570796</max_angle>
          </horizontal>
        </scan>
        <range>
          <min>0.10</min>
          <max>30.0</max>
          <resolution>0.01</resolution>
        </range>
        <noise>
          <type>gaussian</type>
          <!-- Noise parameters based on published spec for Hokuyo laser
               achieving "+-30mm" accuracy at range < 10m.  A mean of 0.0m and
               stddev of 0.01m will put 99.7% of samples within 0.03m of the true
               reading. -->
          <mean>0.0</mean>
          <stddev>0.01</stddev>
        </noise>
      </ray>
      <plugin name="gazebo_ros_head_hokuyo_controller" filename="libgazebo_ros_laser.so">
        <topicName>/scan</topicName>
        <frameName>hokuyo_link</frameName>
      </plugin>
    </sensor>
  </gazebo>
 
</robot>
